<?xml version="1.7" ?>
<sdf version="1.7">

  <model name="my_robot">
    <!--<plugin name="proto_controller" filename="/home/andreap/IIT_CRIS_HHCM/Gazebo_standalone/plugins/my_proto_knee_Task_Tracker/build/libproto_controller.so"/>-->
    <plugin name="libcontrol_plugin" filename="/home/andreap/IIT_CRIS_HHCM/Gazebo_standalone/plugins/my_proto_knee_ISMPC/build/libcontrol_plugin.so"/>

    <pose> 0 0 0 0 0 0 </pose>

    <static>false</static>
  
    <link name='left_wheel'>
          <pose> 0 0.11666666666666668 0.06 0 0 0 </pose>
          <inertial>
            <pose>0 0 0 0 0 0 </pose>
            <mass>0.3</mass>
            <inertia>
              <ixx>0.0005</ixx>
              <ixy>0</ixy>
              <ixz>0</ixz>
              <iyy>0.001</iyy>
              <iyz>0</iyz>
              <izz>0.0005</izz>
            </inertia>
          </inertial>
          <collision name='collision'>
            <max_contacts> 10 </max_contacts> 
            <pose>0 0.04 0 1.5707963267948966 0 0  </pose>
            <geometry>
              <cylinder>
                <radius>0.06 </radius>
                <length>0.01</length>
              </cylinder>
            </geometry>
            <surface>
              <friction>
                <ode>
                  <mu>0.5</mu>
                  <mu2>0.5</mu2>
                  <!--<fdir1>1 0 0</fdir1>
                  <slip1>0.0</slip1>
                  <slip2>0.0</slip2>-->
                </ode>
                <bullet>
                  <friction>0.5</friction>
                  <friction2>0.5</friction2>
                  <!--<fdir1>0 0 0</fdir1>-->
                  <!--<slip1>0.0</slip1>-->
                  <!--<slip2>0.0</slip2>-->
                </bullet>

              </friction>

              <contact>
                <ode>
                  <!--<max_vel>100</max_vel>
                  <min_depth>0.001</min_depth>-->
                  <kp>1000000 </kp>
                  <kd>1</kd>
                </ode>
                <bullet>
                  <kp>1000000</kp>
                  <kd>1</kd>
                </bullet>
              </contact>
            </surface>
          </collision>

          <visual name='visual'>
            <pose>0 0.042 0 0 0 1.5707963267948966</pose>

            <geometry>
              <mesh>
                <uri>model://my_robot_knee/meshes/wheel.dae</uri>
              </mesh>
            </geometry>
          </visual>
    </link>

    <link name='left_ah_link'>
        <pose relative_to='left_wheel'> -0.14009301436927907 -0.015 0.1792489813776607 0 -2.234188956850584 0 </pose>
        <inertial>
          <pose>0 0 0 0 0 0 </pose>
          <mass>0.29483999999999994</mass>
          <inertia>
            <ixx>1.9655999999999996e-05</ixx>
            <ixy>0.0</ixy>
            <ixz>0.0</ixz>
            <iyy>0.005096432249999998</iyy>
            <iyz>0.0</iyz>
            <izz>0.005096432249999998</izz>
          </inertia>
        </inertial>
        <collision name='collision'>
          <pose>0 0 0 0 0 0  </pose>
          <geometry>
            <box>
              <size> 0.45499999999999996 0.02 0.02 </size>
            </box>
          </geometry>
        </collision>
        <visual name='visual'>
        <pose>-0.227 0 0 0 0 1.5707963267948966  </pose>
          <geometry>
              <mesh>
                <uri>model://my_robot_knee/meshes/ah_bar_link_and_actuator.dae</uri>
              </mesh>
              <!--<box>
                <size> 0.45499999999999996 0.02 0.02 </size>
              </box>-->
          </geometry>
        </visual>
    </link>

      <link name='left_d_link'>
        <pose relative_to='left_ah_link'> 0.10966461016744583 0.02 -0.12675132689451746 0 1.7105901812522852 0 </pose>
        <inertial>
          <pose>0 0 0 0 0 0 </pose>
          <mass>0.165888</mass>
          <inertia>
            <ixx>1.10592e-05</ixx>
            <ixy>0.0</ixy>
            <ixz>0.0</ixz>
            <iyy>0.000911499264</iyy>
            <iyz>0.0</iyz>
            <izz>0.000911499264</izz>
          </inertia>
        </inertial>
        <collision name='collision'>
          <pose>0 0 0 0 0 0  </pose>
          <geometry>
            <box>
              <size> 0.256 0.02 0.02 </size>
            </box>
          </geometry>
        </collision>
        <visual name='visual'>
        <pose>0 0 0 0 0 1.5707963267948966  </pose>
          <geometry>
              <mesh>
                <uri>model://my_robot_knee/meshes/bar_d_link.dae</uri>
              </mesh>
              <!--<box>
                <size> 0.256 0.02 0.02 </size>
              </box>-->
          </geometry>
        </visual>
    </link>

    <link name='left_c_link'>
      <pose relative_to='left_ah_link'> 0.23162568522897206 0.02 -0.11792785388275087 0 1.5358257652694682 0 </pose>
      <inertial>
        <pose>0 0 0 0 0 0 </pose>
        <mass>0.15292799999999998</mass>
        <inertia>
          <ixx>1.0195199999999999e-05</ixx>
          <ixy>0.0</ixy>
          <ixz>0.0</ixz>
          <iyy>0.0007148874239999998</iyy>
          <iyz>0.0</iyz>
          <izz>0.0007148874239999998</izz>
        </inertia>
      </inertial>
      <collision name='collision'>
        <pose>0 0 0 0 0 0  </pose>
        <geometry>
          <box>
            <size> 0.236 0.02 0.02 </size>
          </box>
        </geometry>
      </collision>
      <visual name='visual'>
        <pose>0 0 0 0 0 1.5707963267948966  </pose>
          <geometry>
              <mesh>
                <uri>model://my_robot_knee/meshes/bar_c_link.dae</uri>
              </mesh>
              <!--<box>
                <size> 0.236 0.02 0.02 </size>
              </box>-->
          </geometry>
        </visual>
    </link>

    <link name='right_wheel'>
          <max_contacts> 10 </max_contacts> 
          <pose> 0 -0.11666666666666668 0.06 0 0 0 </pose>
          <inertial>
            <pose>0 0 0 0 0 0 </pose>
            <mass>0.3</mass>
            <inertia>
              <ixx>0.0005</ixx>
              <ixy>0</ixy>
              <ixz>0</ixz>
              <iyy>0.001</iyy>
              <iyz>0</iyz>
              <izz>0.0005</izz>
            </inertia>
          </inertial>
          <collision name='collision'>
            <pose>0 -0.04 0 1.5707963267948966 0 0  </pose>
            <geometry>
              <cylinder>
                <radius>0.06 </radius>
                <length>0.01</length>
              </cylinder>
            </geometry>
            <surface>
              <friction>
                <ode>
                  <mu>0.5</mu>
                  <mu2>0.5</mu2>
                  <!--<fdir1>1 0 0</fdir1>
                  <slip1>0.0</slip1>
                  <slip2>0.0</slip2>-->
                </ode>
                <bullet>
                  <friction>0.5</friction>
                  <friction2>0.5</friction2>
                  <!--<fdir1>1 0 0</fdir1>-->
                  <!--<slip1>0.0</slip1>-->
                  <!--<slip2>0.0</slip2>-->
                </bullet>
              </friction>
              <contact>
                <ode>
                  <!--<max_vel>100</max_vel>
                  <min_depth>0.001</min_depth>-->
                  <kp>1000000</kp>
                  <kd>1</kd>
                </ode>
                <bullet>
                  <kp>1000000</kp>
                  <kd>1</kd>
                </bullet>
              </contact>
            </surface>
          </collision>

          <visual name='visual'>
            <pose>0 -0.042 0 0 0 -1.5707963267948966</pose>

            <geometry>
              <mesh>
                <uri>model://my_robot_knee/meshes/wheel.dae</uri>
              </mesh>
            </geometry>
          </visual>
    </link>
    
    <link name='right_ah_link'>
          <pose relative_to='right_wheel'> -0.14009301436927907 0.015 0.1792489813776607 0 -2.234188956850584 0 </pose>
          <inertial>
            <pose>0 0 0 0 0 0 </pose>
            <mass>0.29483999999999994</mass>
            <inertia>
              <ixx>1.9655999999999996e-05</ixx>
              <ixy>0.0</ixy>
              <ixz>0.0</ixz>
              <iyy>0.005096432249999998</iyy>
              <iyz>0.0</iyz>
              <izz>0.005096432249999998</izz>
            </inertia>
          </inertial>
          <collision name='collision'>
            <pose>0 0 0 0 0 0  </pose>
            <geometry>
              <box>
                <size> 0.45499999999999996 0.02 0.02 </size>
              </box>
            </geometry>
          </collision>
          <visual name='visual'>
            <pose>-0.227 0 0 0 3.141592653589793 1.5707963267948966  </pose>
            <geometry>
              <mesh>
                <uri>model://my_robot_knee/meshes/ah_bar_link_and_actuator.dae</uri>
              </mesh>
              <!--<box>
                <size> 0.45499999999999996 0.02 0.02 </size>
              </box>-->
            </geometry>
        </visual>
    </link>

    <link name='right_d_link'>
        <pose relative_to='right_ah_link'> 0.10966461016744583 -0.02 -0.12675132689451746 0 1.7105901812522852 0 </pose>
        <inertial>
          <pose>0 0 0 0 0 0 </pose>
          <mass>0.165888</mass>
          <inertia>
            <ixx>1.10592e-05</ixx>
            <ixy>0.0</ixy>
            <ixz>0.0</ixz>
            <iyy>0.000911499264</iyy>
            <iyz>0.0</iyz>
            <izz>0.000911499264</izz>
          </inertia>
        </inertial>
        <collision name='collision'>
          <pose>0 0 0 0 0 0  </pose>
          <geometry>
            <box>
              <size> 0.256 0.02 0.02 </size>
            </box>
          </geometry>
      </collision>
      <visual name='visual'>
            <pose>0 0 0 0 0 1.5707963267948966  </pose>
            <geometry>
              <mesh>
                <uri>model://my_robot_knee/meshes/bar_d_link.dae</uri>
              </mesh>
              <!--<box>
                <size> 0.256 0.02 0.02 </size>
              </box>-->
            </geometry>
      </visual>
    </link>

    <link name='right_c_link'>
      <pose relative_to='right_ah_link'> 0.23162568522897206 -0.02 -0.11792785388275087 0 1.5358257652694682 0 </pose>
      <inertial>
        <pose>0 0 0 0 0 0 </pose>
        <mass>0.15292799999999998</mass>
        <inertia>
          <ixx>1.0195199999999999e-05</ixx>
          <ixy>0.0</ixy>
          <ixz>0.0</ixz>
          <iyy>0.0007148874239999998</iyy>
          <iyz>0.0</iyz>
          <izz>0.0007148874239999998</izz>
        </inertia>
      </inertial>
      <collision name='collision'>
        <pose>0 0 0 0 0 0  </pose>
        <geometry>
          <box>
            <size> 0.236 0.02 0.02 </size>
          </box>
        </geometry>
      </collision>
      <visual name='visual'>
            <pose>0 0 0 0 0 1.5707963267948966  </pose>
            <geometry>
              <mesh>
                <uri>model://my_robot_knee/meshes/bar_c_link.dae</uri>
              </mesh>
              <!--<box>
                <size> 0.236 0.02 0.02 </size>
              </box>-->
            </geometry>
        </visual>
    </link>

    <link name='body'>
        <pose relative_to='right_d_link'> 0.10923561923006725 0.12166666666666667 0.07002962240595745 0 0.5235987755982991 0 </pose>
        <inertial>
          <pose> 0.06566574413589875 0 -0.04080266414521867 0 0 0 </pose>
          <mass> 10 </mass>
          <inertia>
            <ixx>0.2</ixx>
            <ixy>0</ixy>
            <ixz>0</ixz>
            <iyy>0.1</iyy>
            <iyz>0</iyz>
            <izz>0.2</izz>
          </inertia>
        </inertial>
        <collision name='collision'>
          <pose>0 0 0 0 0 0</pose>
          <geometry>
            <box>
              <size> 0.145 0.22333333333333336 0.145 </size>
            </box>
          </geometry>
        </collision>
        <visual name='visual'>
        <pose>0 0.09333333333333335 -0.07 0 0 4.71238898038469  </pose>
              
              <geometry>
              <mesh>
                <uri>model://my_robot_knee/meshes/frame.dae</uri>
              </mesh>
              <!--<box>
                <size> 0.145 0.22333333333333336 0.145 </size>
              </box>-->
          </geometry>
        </visual>
    </link> 


      <joint type="revolute" name="left_wheel_hinge">
        <pose>0 0 0 0 0 0</pose>
        <child>left_wheel</child>
        <parent>left_ah_link</parent>
        <axis>
          <xyz>0 1 0</xyz>
          <dynamics>
            <!--<damping> 0 </damping>
            <spring_reference> 0 </spring_reference>
            <spring_stiffness> 0 </spring_stiffness>-->
          </dynamics>
          <limit>
            <!--<lower>  </lower>
            <upper>  </upper>
            <effort> </effort>-->
          </limit>
        </axis>
      </joint>

      <joint type="revolute" name="left_ah_d_hinge">
        <pose>0.12749999999999997 0 0 0 0 0</pose>
        <child>left_ah_link</child>
        <parent>left_d_link</parent>
        <axis>
          <xyz>0 1 0</xyz>
          <dynamics>
            <!--<damping> 0 </damping>
            <spring_reference> 0 </spring_reference>
            <spring_stiffness> 0 </spring_stiffness>-->
          </dynamics>
          <limit>
            <!--<lower>  </lower>
            <upper>  </upper>
            <effort> </effort>-->
          </limit>
        </axis>
      </joint>

      <joint type="revolute" name="left_ah_c_hinge">
        <pose>0.22749999999999998 0 0 0 0 0</pose>
        <child>left_ah_link</child>
        <parent>left_c_link</parent>
        <axis>
          <xyz>0 1 0</xyz>
          <dynamics>
            <damping> 0 </damping>
            <spring_reference> 0.4229179171574249 </spring_reference>
            <spring_stiffness> 30.0 </spring_stiffness>
          </dynamics>
          <limit>
            <!--<lower>  </lower>
            <upper>  </upper>
            <effort> </effort>-->
          </limit>
        </axis>
    </joint>


    <joint type="revolute" name="right_wheel_hinge">
      <pose>0 0 0 0 0 0</pose>
      <child>right_wheel</child>
      <parent>right_ah_link</parent>
      <axis>
        <xyz>0 1 0</xyz>
        <dynamics>
          <!--<damping> 0 </damping>
          <spring_reference>  </spring_reference>
          <spring_stiffness>  0 </spring_stiffness>-->
        </dynamics>
        <limit>
          <!--<lower> </lower>
          <upper> </upper>
          <effort> </effort>-->
        </limit>
      </axis>
    </joint>

    <joint type="revolute" name="right_ah_d_hinge">
      <pose>0.12749999999999997 0 0 0 0 0</pose>
      <child>right_ah_link</child>
      <parent>right_d_link</parent>
      <axis>
        <xyz>0 1 0</xyz>
        <dynamics>
          <!--<damping>  </damping>
          <spring_reference>  </spring_reference>
          <spring_stiffness>  0 </spring_stiffness>-->
        </dynamics>
        <limit>
          <!--<lower>     </lower>
          <upper>      </upper>
          <effort>    </effort>-->
        </limit>
      </axis>
    </joint>

    <joint type="revolute" name="right_ah_c_hinge">
      <pose>0.22749999999999998 0 0 0 0 0</pose>
      <child>right_ah_link</child>
      <parent>right_c_link</parent>
      <axis>
        <xyz>0 1 0</xyz>
        <dynamics>
          <damping> 0 </damping>
          <spring_reference> 0.4229179171574249 </spring_reference>
          <spring_stiffness> 30.0 </spring_stiffness>
        </dynamics>
        <limit>
          <!--<lower>  </lower>
          <upper>  </upper>
          <effort> </effort>-->
        </limit>
      </axis>
    </joint>


    <joint type="revolute" name="left_c_body_hinge">
      <pose>0.118 0 0 0 0 0</pose>
      <child>left_c_link</child>
      <parent>body</parent>
      <axis>
        <xyz>0 1 0</xyz>
        <dynamics>
          <!--<damping> 0 </damping>
          <spring_reference>  </spring_reference>
          <spring_stiffness> 0  </spring_stiffness>-->
        </dynamics>
        <limit>
          <!--<lower>  </lower>
          <upper>  </upper>
          <effort> </effort>-->
        </limit>
      </axis>
    </joint>

    <joint type="revolute" name="left_d_body_hinge">
      <pose>0.128 0 0 0 0 0</pose>
      <child>left_d_link</child>
      <parent>body</parent>
      <axis>
        <xyz>0 1 0</xyz>
        <dynamics>
          <damping> 0 </damping>
          <!--<spring_reference>  </spring_reference>
          <spring_stiffness> 0 </spring_stiffness>-->
        </dynamics>
        <limit>
          <lower> -0.5235987755982989 </lower>
          <upper> 0.22689280275926293 </upper>
          <stiffness> 100000000  </stiffness> 
          <dissipation> 1 </dissipation>
          <!--<effort> 20 </effort>-->
        </limit>
      </axis>
    </joint>

    <joint type="revolute" name="right_c_body_hinge">
      <pose>0.118 0 0 0 0 0</pose>
      <child>right_c_link</child>
      <parent>body</parent>
      <axis>
        <xyz>0 1 0</xyz>
        <dynamics>
          <!--<damping> 0 </damping>
          <spring_reference>  </spring_reference>
          <spring_stiffness>  0  </spring_stiffness>-->
        </dynamics>
        <limit>
          <!--<lower>  </lower>
          <upper>  </upper>
          <effort> </effort>-->
        </limit>
      </axis>
    </joint>

    <joint type="revolute" name="right_d_body_hinge">
      <pose>0.128 0 0 0 0 0</pose>
      <child>right_d_link</child>
      <parent>body</parent>
      <axis>
        <xyz>0 1 0</xyz>
        <dynamics>
          <damping> 0 </damping>
          <!--<spring_reference>  </spring_reference>
          <spring_stiffness> 0 </spring_stiffness>-->
        </dynamics>
        <limit>
          <lower> -0.5235987755982989   </lower>
          <upper> 0.22689280275926293   </upper>
          <stiffness> 100000000  </stiffness> 
          <dissipation> 1 </dissipation>
          <effort> 20 </effort>
        </limit>
      </axis>
    </joint>


  </model>
</sdf>